Workbook

Sheet Model_Spec_Operational_Downtime
A1: Compliance Circle – CoNC | B1: Operational Downtime (Core System Outage) – Model Specification (Excel → Code)
A3: Purpose | B3: This sheet specifies the Operational Downtime model in a structured, code-friendly way. It documents inputs, data tables, mapping rules, formulas, constraints, and test cases so the model can be implemented 1:1 (e.g., by Rune using Claude) without relying on cell positions.
A5: Data Tables (Source of Truth)
A6: Table | B6: Description / Fields | C6: Sheet
A7: tbl_IT_Dependency | B7: Level → Factor. Used to scale daily revenue exposure based on operational IT dependency. Fields: Level, Factor, Source/Note. | C7: DT_Config
A8: EU_Sector_Map | B8: Deterministic EU sector → IBM industry mapping. No averaging or weighting. Fields: EU Sector, Mapped IBM Industry. | C8: EU_Sector_Map
A9: IBM_Calibration | B9: IBM 2025 industry costs + linear normalisation to 0.90–1.10 sector factors. Fields: IBM Industry, IBM Cost, Min/Max/Range, Sector Factor. | C9: IBM_Calibration
A10: tbl_Sector_Factors | B10: EU Sector → Factor (derived). Each EU sector inherits the factor of its mapped IBM industry. Fields: Sector, Factor, Source/Note. | C10: DT_Config
A11: tbl_GAP_Downtime | B11: GAP score reference table for transparency and validation. Note: downtime_days is implemented via the continuous formula below (no lookup required). Fields: Min score (>=), Days, Note. | C11: DT_Config
A12: tbl_EU_Sectors | B12: EU sector selection list for dropdowns. Field: EU Sector. | C12: DT_Config
A14: Sector Factor Logic
A15: Rule | B15: EU sectors are used throughout the platform. For Operational Downtime, each EU sector is mapped 1:1 to a single IBM industry category. The EU sector inherits the IBM-derived sector factor. No blending/averaging across multiple IBM categories is applied.
A17: IBM Normalisation (±10%)
A18: Formula | B18: sector_factor = 0.90 + ((IBM_cost - min_cost) / (max_cost - min_cost)) * 0.20 where min_cost and max_cost are taken from the full set of IBM industries (not a subset).
A20: Continuous GAP → Downtime Days
A21: Formula | B21: gap_score (0–100) is computed from 8 maturity questions (DT_Q1–DT_Q8), each answered on a 1–5 scale: gap_score = ((AVG(answers) - 1) / 4) * 100 downtime_days = MAX(0.5, 3 - (gap_score / 100) * 2.5) The GAP score is treated as a continuous variable so incremental improvements translate proportionally into reduced expected downtime. Minimum expected downtime is 0.5 days and maximum is 3.0 days.
A23: Operational Downtime Cost
A24: Formula | B24: daily_revenue = annual_revenue / business_days operational_downtime_cost = daily_revenue * IT_factor * sector_factor * downtime_days Output should be presented as Low / Mid / High by applying ±30% around the mid estimate.
A26: Constraints
A27: Bounds | B27: 0.90 ≤ sector_factor ≤ 1.10 0.5 ≤ downtime_days ≤ 3.0 IT_factor ∈ {0.3, 0.6, 0.9}
A29: Test Cases (expected sector factors)
A30: EU Sector | B30: Expected factor (approx) | C30: Mapped IBM Industry
A31: Q – Healthcare | B31: 1.10 | C31: Healthcare
A32: O – Public Administration | B32: 0.90 | C32: Public
A33: K – Financial Services | B33: 1.02 | C33: Financial
A34: G – Wholesale/Retail | B34: 0.93 | C34: Retail
A35: J – IT/Telecom | B35: 0.98 | C35: Technology

Sheet Introduction
A1: Introduction to Cost of Operational Downtime Estimation
A2: This is part of the CoNC (Cost of non compliance) module in Compliance circle. The purpose is to provide a fast estimation of the cost a SME will be facing if they are to experience a data breach. The module consist of 9 areas of cost calculations: Operational Impact 1) Operational Downtime (Core System Outage) 2) Incident Response & Forensics 3) System Restoration & Rebuild 4) Business Interruption (Extended) Commercial Impact 5) Customer & Contract Loss 6) Reputational Impact (Sector dependent) Regulatory Exposure 7) Regulatory & Supervisory Cost 8) Administrative Fine Ceiling Governance Cost 9) Management & Governance Cost
A4: Cost of Operational Downtime Estimation
A5: Formål At estimere omsætnings-/driftstab ved et core system outage som en range (Low / Mid / High) baseret på: - kundens egne nøgletal (revenue) - hvor IT-afhængig driften er - konservativ branchejustering - et mini-GAP (resiliens) der estimerer forventet downtime-varighed
A6: Estimation steps (Factors) | B6: Description | F6: Notes | L6: Sources & Treatment
A7: 1 Baseline business exposure | B7: We start with a simple baseline for how much business value is exposed per operating day. This provides a neutral reference point based on the client’s own financial data, before any adjustments for IT dependency and resilience are applied. It represents the maximum potential daily exposure under normal operating conditions. | F7: Daily revenue exposure = Annual revenue / Business days Default = 220 business days (can be adjusted if relevant)
A8: 2) Operational dependency on IT | B8: Not all companies lose 100% of their revenue during an IT outage. This step estimates how much of the core business operation is realistically dependent on IT systems. The objective is to apply a conservative and robust adjustment factor that: - is easy to explain - does not require perfect data - can be overridden by an advisor when better insight is available | F8: Dependency is classified as Low / Medium / High IT factor: Low = 0,3 Medium = 0,6 High = 0,9 IT-adjusted daily loss = Daily revenue exposure × IT factor | L8: IT dependency is assessed using three structured questions covering: (1) ability to operate manually during outages, (2) dependency of production and delivery on IT systems (3) customer access to digital platforms and services. Each question is scored 0–2 (0 = low dependency, 1 = partial dependency, 2 = high dependency). The total score (0–6) is mapped as follows: 0–1 = Low, 2–3 = Medium, 4–6 = High. These levels are translated into conservative impact factors (0,3 / 0,6 / 0,9).
A9: 3) Sector adjustment | B9: Some industries are structurally more exposed to operational disruption than others (for example due to time-critical delivery, production processes, or contractual obligations). The sector adjustment is used as a moderate relative calibration factor. Key principle: - the client’s own revenue and IT dependency remain the primary drivers - the sector factor is applied as a “light-touch” modifier to avoid model bias | F9: Sector factors are limited to a conservative range of 0.90–1.10 and recalibrated annually using updated IBM data. Client-specific revenue and IT dependency remain the primary drivers. Sector-adjusted daily loss = IT-adjusted daily loss × Sector factor | L9: IBM Cost of a Data Breach Report 2025 (Industry analysis, Figure 3) is used solely as a reference for relative differences between sectors. Reported costs include multiple impact categories (legal, response, reputation, etc.) and are therefore not used as absolute downtime values. Sector factors are derived from relative differences between industries in the report and translated into a limited multiplier range.
A10: 4) Resilience / maturity | B10: This step translates the client’s operational resilience and maturity (mini-GAP assessment) into an estimated duration of a core system outage. The underlying logic is: - low maturity → longer recovery time (weak backup, unclear roles, limited monitoring) - high maturity → shorter recovery time (tested recovery, clear incident response, redundancy) - a minimum floor is applied, as even well-prepared organisations rarely experience “zero impact” | F10: GAP score is normalised to 0–100 The GAP score is treated as a continuous variable to ensure that incremental improvements in resilience translate proportionally into reduced expected downtime. Expected downtime is bounded between a minimum of 0,5 days and a maximum of 3,0 days. downtime_days = MAX(0,5 ; 3 - (gap_score/100) × 2,5) | L10: The mini-GAP assessment is based on the following eight structured questions: - Do you perform daily backups of all critical systems? - Are backups stored off-site or immutable (protected from ransomware)? - Have backup restores been tested within the last 12 months? - Do you have a documented incident response plan? - Are roles and responsibilities defined for incident handling? - Have incident response exercises been conducted within the last 12 months? - Are critical systems protected against single points of failure? - Is continuous monitoring in place for core infrastructure? Each question is scored 0–2: (0 = No / ad hoc, 1 = Partial / informal, 2 = Yes / formalised and tested). Scores are averaged and normalised to a 0–100 scale: GAP_score_calc = AVERAGE(DT_Q1:DT_Q8) / 2 × 100
A11: 5) Downtime impact (range) | B11: The final downtime cost is presented as a range (Low / Mid / High) in order to avoid false precision. | F11: Downtime cost (mid) = Sector-adjusted daily loss × downtime_days Range factors: - Low = Mid × 0,7 - Mid = Mid × 1,0 - High = Mid × 1,3

Sheet DT_Helper
A1: Helper Text – CoNC Operational Downtime (Mini-GAP)
A2: Answer coding: 0 = No/Not formalized/Ad-hoc, 1 = Partlally/Informal/Limited axope, 2 = Yes/Formalized/Covers all critical systems. Use these definitions to answer consistently. Score based on impact on revenue, not internal inconvenience.
A4: Downtime GAP (DT_Q1–DT_Q8)
A5: Purpose | B5: Assess how quickly the organization can realistically recover from a major system outage.
A7: DT_Q1 — Daily Backups | B7: Do you perform daily backups of all critical systems?
A8: DT_Q2 — Offsite / Immutable Backups | B8: Are backups stored off-site or immutable (protected from ransomware)?
A9: DT_Q3 — Restore Testing | B9: Have backup restores been tested within the last 12 months?
A10: DT_Q4 — Incident Response Plan | B10: Do you have a documented incident response plan?
A11: DT_Q5 — Defined Roles | B11: Are roles and responsibilities defined for incident handling?
A12: DT_Q6 — Incident Exercises | B12: Have incident response exercises been conducted within the last 12 months?
A13: DT_Q7 — Infrastructure Resilience | B13: Are critical systems protected against single points of failure?
A14: DT_Q8 — Monitoring | B14: Is continuous monitoring in place for core infrastructure?
A15: Interpretation | B15: Higher scores indicate stronger resilience and typically fewer downtime days.
A17: IT Dependency (DEP_Q9–DEP_Q11)
A18: Purpose | B18: Estimate how much of the business stops (and how much revenue is affected) when IT is unavailable.
A20: DEP_Q9 — Manual Operation | B20: Can core revenue-generating operations continue manually for more than 24 hours?
A21: DEP_Q10 — Production Dependency | B21: Does production/delivery depend directly on IT systems in a way that stops billing, delivery, or fulfillment?
A22: DEP_Q11 — Customer Access | B22: Is customer access required for sales, orders, or service delivery? (e.g. portal, SaaS, API, Booking system)?
A23: Interpretation | B23: Higher scores indicate higher dependency, meaning a larger daily loss when systems are down.

Sheet DT_Config
A1: CoNC – Operational Downtime (Internal Test Rig) | H1: Model version | I1: CoNC-DT-v1.2
A2: Config tables only (no formulas). Edit values here to calibrate the model. | H2: Date | I2: 2026-02-20
H3: Notes | I3: Added DT_Helper sheet + header tooltips for Mini-GAP questions
A4: Business days / year (default) | B4: 220
A6: IT dependency factors
A7: Level | B7: Factor | C7: Source / note
A8: Low | B8: 0.3 | C8: Calibration v1 (conservative)
A9: Medium | B9: 0.6 | C9: Calibration v1 (conservative)
A10: High | B10: 0.9 | C10: Calibration v1 (conservative)
A13: Sector factors | E13: EU sectors (selection list)
A14: Sector | B14: Factor | C14: Source / note | E14: EU Sector
A15: A – Agriculture | B15: =INDEX(IBM_Calibration!$G$2:$G$18, MATCH(INDEX(EU_Sector_Map!$B$2:$B$20, MATCH(A15, EU_Sector_Map!$A$2:$A$20, 0)), IBM_Calibration!$A$2:$A$18, 0)) -> 0.99385965 | C15: Mapped via EU_Sector_Map to a single IBM industry category. IBM sector factors are derived from IBM Cost of a Data Breach 2025 (Figure 3) and linearly normalised to a symmetric 0.90–1.10 range (see IBM_Calibration). | E15: A – Agriculture
A16: B – Mining | B16: =INDEX(IBM_Calibration!$G$2:$G$18, MATCH(INDEX(EU_Sector_Map!$B$2:$B$20, MATCH(A16, EU_Sector_Map!$A$2:$A$20, 0)), IBM_Calibration!$A$2:$A$18, 0)) -> 0.99385965 | C16: Mapped via EU_Sector_Map to a single IBM industry category. IBM sector factors are derived from IBM Cost of a Data Breach 2025 (Figure 3) and linearly normalised to a symmetric 0.90–1.10 range (see IBM_Calibration). | E16: B – Mining
A17: C – Manufacturing | B17: =INDEX(IBM_Calibration!$G$2:$G$18, MATCH(INDEX(EU_Sector_Map!$B$2:$B$20, MATCH(A17, EU_Sector_Map!$A$2:$A$20, 0)), IBM_Calibration!$A$2:$A$18, 0)) -> 0.99385965 | C17: Mapped via EU_Sector_Map to a single IBM industry category. IBM sector factors are derived from IBM Cost of a Data Breach 2025 (Figure 3) and linearly normalised to a symmetric 0.90–1.10 range (see IBM_Calibration). | E17: C – Manufacturing
A18: D – Energy/Utilities | B18: =INDEX(IBM_Calibration!$G$2:$G$18, MATCH(INDEX(EU_Sector_Map!$B$2:$B$20, MATCH(A18, EU_Sector_Map!$A$2:$A$20, 0)), IBM_Calibration!$A$2:$A$18, 0)) -> 0.98640351 | C18: Mapped via EU_Sector_Map to a single IBM industry category. IBM sector factors are derived from IBM Cost of a Data Breach 2025 (Figure 3) and linearly normalised to a symmetric 0.90–1.10 range (see IBM_Calibration). | E18: D – Energy/Utilities
A19: E – Water/Waste | B19: =INDEX(IBM_Calibration!$G$2:$G$18, MATCH(INDEX(EU_Sector_Map!$B$2:$B$20, MATCH(A19, EU_Sector_Map!$A$2:$A$20, 0)), IBM_Calibration!$A$2:$A$18, 0)) -> 0.98640351 | C19: Mapped via EU_Sector_Map to a single IBM industry category. IBM sector factors are derived from IBM Cost of a Data Breach 2025 (Figure 3) and linearly normalised to a symmetric 0.90–1.10 range (see IBM_Calibration). | E19: E – Water/Waste
A20: F – Construction | B20: =INDEX(IBM_Calibration!$G$2:$G$18, MATCH(INDEX(EU_Sector_Map!$B$2:$B$20, MATCH(A20, EU_Sector_Map!$A$2:$A$20, 0)), IBM_Calibration!$A$2:$A$18, 0)) -> 0.99385965 | C20: Mapped via EU_Sector_Map to a single IBM industry category. IBM sector factors are derived from IBM Cost of a Data Breach 2025 (Figure 3) and linearly normalised to a symmetric 0.90–1.10 range (see IBM_Calibration). | E20: F – Construction
A21: G – Wholesale/Retail | B21: =INDEX(IBM_Calibration!$G$2:$G$18, MATCH(INDEX(EU_Sector_Map!$B$2:$B$20, MATCH(A21, EU_Sector_Map!$A$2:$A$20, 0)), IBM_Calibration!$A$2:$A$18, 0)) -> 0.92982456 | C21: Mapped via EU_Sector_Map to a single IBM industry category. IBM sector factors are derived from IBM Cost of a Data Breach 2025 (Figure 3) and linearly normalised to a symmetric 0.90–1.10 range (see IBM_Calibration). | E21: G – Wholesale/Retail
A22: H – Transportation | B22: =INDEX(IBM_Calibration!$G$2:$G$18, MATCH(INDEX(EU_Sector_Map!$B$2:$B$20, MATCH(A22, EU_Sector_Map!$A$2:$A$20, 0)), IBM_Calibration!$A$2:$A$18, 0)) -> 0.94912281 | C22: Mapped via EU_Sector_Map to a single IBM industry category. IBM sector factors are derived from IBM Cost of a Data Breach 2025 (Figure 3) and linearly normalised to a symmetric 0.90–1.10 range (see IBM_Calibration). | E22: H – Transportation
A23: I – Hospitality | B23: =INDEX(IBM_Calibration!$G$2:$G$18, MATCH(INDEX(EU_Sector_Map!$B$2:$B$20, MATCH(A23, EU_Sector_Map!$A$2:$A$20, 0)), IBM_Calibration!$A$2:$A$18, 0)) -> 0.95131579 | C23: Mapped via EU_Sector_Map to a single IBM industry category. IBM sector factors are derived from IBM Cost of a Data Breach 2025 (Figure 3) and linearly normalised to a symmetric 0.90–1.10 range (see IBM_Calibration). | E23: I – Hospitality
A24: J – IT/Telecom | B24: =INDEX(IBM_Calibration!$G$2:$G$18, MATCH(INDEX(EU_Sector_Map!$B$2:$B$20, MATCH(A24, EU_Sector_Map!$A$2:$A$20, 0)), IBM_Calibration!$A$2:$A$18, 0)) -> 0.98464912 | C24: Mapped via EU_Sector_Map to a single IBM industry category. IBM sector factors are derived from IBM Cost of a Data Breach 2025 (Figure 3) and linearly normalised to a symmetric 0.90–1.10 range (see IBM_Calibration). | E24: J – IT/Telecom
A25: K – Financial Services | B25: =INDEX(IBM_Calibration!$G$2:$G$18, MATCH(INDEX(EU_Sector_Map!$B$2:$B$20, MATCH(A25, EU_Sector_Map!$A$2:$A$20, 0)), IBM_Calibration!$A$2:$A$18, 0)) -> 1.0184211 | C25: Mapped via EU_Sector_Map to a single IBM industry category. IBM sector factors are derived from IBM Cost of a Data Breach 2025 (Figure 3) and linearly normalised to a symmetric 0.90–1.10 range (see IBM_Calibration). | E25: K – Financial Services
A26: L – Real Estate | B26: =INDEX(IBM_Calibration!$G$2:$G$18, MATCH(INDEX(EU_Sector_Map!$B$2:$B$20, MATCH(A26, EU_Sector_Map!$A$2:$A$20, 0)), IBM_Calibration!$A$2:$A$18, 0)) -> 0.9745614 | C26: Mapped via EU_Sector_Map to a single IBM industry category. IBM sector factors are derived from IBM Cost of a Data Breach 2025 (Figure 3) and linearly normalised to a symmetric 0.90–1.10 range (see IBM_Calibration). | E26: L – Real Estate
... A33: S – Other Services | B33: =INDEX(IBM_Calibration!$G$2:$G$18, MATCH(INDEX(EU_Sector_Map!$B$2:$B$20, MATCH(A33, EU_Sector_Map!$A$2:$A$20, 0)), IBM_Calibration!$A$2:$A$18, 0)) -> 0.9745614 | C33: Mapped via EU_Sector_Map to a single IBM industry category. IBM sector factors are derived from IBM Cost of a Data Breach 2025 (Figure 3) and linearly normalised to a symmetric 0.90–1.10 range (see IBM_Calibration). | E33: S – Other Services
E34: J – IT/Telecom
A35: Downtime GAP score → typical downtime (days) | E35: K – Financial Services
A36: Min score (>=) | B36: Days | C36: Note | E36: L – Real Estate
A37: 80 | B37: 0.5 | C37: High resilience (calibration v1) | E37: M – Professional Services
A38: 65 | B38: 1 | C38: Medium resilience (calibration v1) | E38: N – Administrative Services
A39: 45 | B39: 2 | C39: Low resilience (calibration v1) | E39: O – Public Administration
A40: 0 | B40: 3 | C40: Very low resilience (calibration v1) | E40: P – Education
E41: Q – Healthcare
A42: Output range factors | E42: R – Entertainment
A43: Label | B43: Factor | C43: Note | E43: S – Other Services
A44: Low | B44: 0.7 | C44: Conservative lower bound
A45: Mid | B45: 1 | C45: Point estimate
A46: High | B46: 1.3 | C46: Conservative upper bound
A49: IR Dependency Multiplier (used for Incident Response & Forensics cost adjustment)
A50: IT Dependency Level | B50: IR_Dependency_Multiplier | C50: Note
A51: Low | B51: 0.85 | C51: Lower system complexity
...

Sheet DT_Calc
A1: Step-by-step Calculation (row-by-row)
A2: This sheet is formula-only. Inputs come from DT_Scenarios (selected scenario).
A4: Selected scenario ID (DT_Scenarios) | B4: 1
A6: Step | B6: Value | C6: Notes
A7: Annual revenue | B7: =VLOOKUP($B$4,DT_Scenarios!$A$5:$H$200,3,FALSE()) -> 75000000 | C7: From scenarios (DKK)
A8: Business days / year | B8: =IF(ISBLANK(VLOOKUP($B$4,DT_Scenarios!$A$5:$H$200,7,FALSE())),DT_Config!$B$4,VLOOKUP($B$4,DT_Scenarios!$A$5:$H$200,7,FALSE())) -> 220 | C8: Override optional; default from config
A9: Daily revenue | B9: =B7/B8 -> 340909.09 | C9: Annual revenue / business days
A10: IT dependency level | B10: =IF(ISBLANK(INDEX(DT_Scenarios!$E:$E,MATCH($B$4,DT_Scenarios!$A:$A,0))),INDEX(DT_Scenarios!$U:$U,MATCH($B$4,DT_Scenarios!$A:$A,0)),INDEX(DT_Scenarios!$E:$E,MATCH($B$4,DT_Scenarios!$A:$A,0))) -> High | C10: Manual override optional; otherwise auto-calculated from DEP_Q9–DEP_Q11
A11: IT factor | B11: =INDEX(tbl_IT_Dependency[Factor], MATCH(B10, tbl_IT_Dependency[Level], 0)) -> 0.9 | C11: Lookup from config
A12: Sector | B12: =VLOOKUP($B$4,DT_Scenarios!$A$5:$H$200,4,FALSE()) -> J – IT/Telecom | C12: Sector selection
A13: Sector factor | B13: =INDEX(tbl_Sector_Factors[Factor], MATCH(B12, tbl_Sector_Factors[Sector], 0)) -> 0.98464912 | C13: Lookup from config
A14: Adjusted daily loss | B14: =B9*B11*B13 -> 302108.25 | C14: Daily revenue × IT factor × sector factor
A15: Downtime GAP score | B15: =IF(INDEX(DT_Scenarios!$F:$F,MATCH($B$4,DT_Scenarios!$A:$A,0))="",INDEX(DT_Scenarios!$P:$P,MATCH($B$4,DT_Scenarios!$A:$A,0)),INDEX(DT_Scenarios!$F:$F,MATCH($B$4,DT_Scenarios!$A:$A,0))) -> 12.5 | C15: Manual override optional; otherwise auto-calculated from DT_Q1–DT_Q8
A16: Downtime days | B16: =MAX(0.5, 3 - (B15/100)*2.5) -> 2.6875 | C16: Mapping table in config
A17: Downtime cost (mid) | B17: =B14*B16 -> 811915.93 | C17: Adjusted daily loss × downtime days
A18: Downtime cost (low) | B18: =B17*0.7 -> 568341.15 | C18: Mid × low range factor
A19: Downtime cost (high) | B19: =B17*1.3 -> 1055490.7 | C19: Mid × high range factor
A21: Checks
A22: IT factor in allowed set | B22: =OR(B11=0.3,B11=0.6,B11=0.9) -> TRUE | C22: OK / FAIL
A23: Sector factor within 0.90–1.10 | B23: =AND(B13>=0.9,B13<=1.1) -> TRUE | C23: OK / FAIL
A24: Downtime days in allowed set | B24: =AND(B16>=0.5,B16<=3) -> TRUE | C24: OK / FAIL
A25: Range monotonic (low < mid < high) | B25: =AND(B18<B17,B17<B19) -> TRUE | C25: OK / FAIL
A32: Incident Response & Forensics (IR)
A33: Description: | B33: IR cost models the expected handling cost of a cyber incident (forensics, legal, crisis management). It consists of a benchmark base cost (revenue-dependent), adjusted by IR maturity and IT dependency.
A35: IR Base (Revenue benchmark) | B35: =IF(B7<50000000,500000,IF(B7<250000000,1200000,3000000)) -> 1200000
A36: IR Score (1–5 avg of IR controls) | B36: =IFERROR(SUM(IFERROR(INDEX(DT_Scenarios!$K:$K,MATCH($B$4,DT_Scenarios!$A:$A,0)),""),IFERROR(INDEX(DT_Scenarios!$L:$L,MATCH($B$4,DT_Scenarios!$A:$A,0)),""),IFERROR(INDEX(DT_Scenarios!$M:$M,MATCH($B$4,DT_Scenarios!$A:$A,0)),""))/MAX(1,COUNT(INDEX(DT_Scenarios!$K:$K,MATCH($B$4,DT_Scenarios!$A:$A,0)),INDEX(DT_Scenarios!$L:$L,MATCH($B$4,DT_Scenarios!$A:$A,0)),INDEX(DT_Scenarios!$M:$M,MATCH($B$4,DT_Scenarios!$A:$A,0)))),3) -> 1
A37: IR Maturity Multiplier | B37: =1.3 - ((B36 - 1)/4) * 0.5 -> 1.3
A38: IR Dependency Multiplier | B38: =INDEX(tbl_IR_Dependency[IR_Dependency_Multiplier], MATCH(B10, tbl_IR_Dependency[IT Dependency Level], 0)) -> 1.15
A39: IR Cost (Mid) | B39: =B35*B37*B38 -> 1794000
A42: System Restoration & Rebuild
A43: Description: | B43: Restore & Rebuild cost models the technical recovery effort following an incident. It includes system reinstallation, cloud re-provisioning, data restoration and validation. It excludes lost business (Downtime) and forensic handling (IR). Cost is based on revenue benchmark, adjusted by backup maturity and IT dependency.
A45: Restore Base (Revenue benchmark) | B45: =INDEX(tbl_Restore_Base[Restore_Base_Mid],MATCH($B$7,tbl_Restore_Base[Min Revenue (DKK)],1)) -> 1000000
A46: Restore Score (Backup maturity avg 1–5) | B46: =IFERROR(AVERAGE(IFERROR(INDEX(DT_Scenarios!$H:$H,MATCH($B$4,DT_Scenarios!$A:$A,0)),1),IFERROR(INDEX(DT_Scenarios!$I:$I,MATCH($B$4,DT_Scenarios!$A:$A,0)),1),IFERROR(INDEX(DT_Scenarios!$J:$J,MATCH($B$4,DT_Scenarios!$A:$A,0)),1)),1) -> 2.3333333
A47: Restore Maturity Multiplier | B47: =1.3 - ((B46 - 1)/4) * 0.5 -> 1.1333333
A48: Restore Dependency Multiplier | B48: =INDEX(tbl_Restore_Dependency[Restore_Dependency_Multiplier], MATCH(B10, tbl_Restore_Dependency[IT Dependency Level], 0)) -> 1.15
A49: Restore Cost (Mid) | B49: =B45*B47*B48 -> 1303333.3
A52: Extended Business Interruption (EBI)
A53: Description: | B53: EBI models the extended operational inefficiency after core systems are restored. It captures reduced productivity, backlog clearing, manual workarounds and delivery disruption. It is anchored to downtime_days (from Operational Downtime) but uses milder sector/dependency effects and restore maturity to reflect recovery friction. It excludes pure lost revenue (Downtime), forensic handling (IR) and technical rebuild work (Restore & Rebuild).
A55: EBI Recovery baseline | B55: =INDEX(tbl_EBI_Params[Value], MATCH("EBI_Recovery_Baseline", tbl_EBI_Params[Parameter], 0)) -> 0.5
A56: EBI Sector adjustment (compressed) | B56: =1 + ((Sector_Factor - 1) * INDEX(tbl_EBI_Params[Value], MATCH("EBI_Sector_Compression", tbl_EBI_Params[Parameter], 0))) -> 0.99232456
...

Sheet DT_Scenarios
B1: Operational Downtime – Scenario Table
B2: Edit / add scenarios here. DT_Calc reads the selected row (set in DT_Calc!B4).
H3: Answer coding (Downtime GAP questions DT_Q1–DT_Q8): 1–5 (CMMI-style maturity). 1=Initial, 2=Managed, 3=Defined, 4=Quantitatively Managed, 5=Optimizing. Leave manual IT dependency / Downtime GAP blank to auto-calc.
A4: ID | B4: Case name | C4: Annual revenue (DKK) | D4: Sector | E4: IT dependency | F4: Downtime GAP score (0–100) | G4: Business days override (optional) | H4: DT_Q1 (1–5) | I4: DT_Q2 (1–5) | J4: DT_Q3 (1–5) | K4: DT_Q4 (1–5) | L4: DT_Q5 (1–5) | M4: DT_Q6 (1–5) | N4: DT_Q7 (1–5) | O4: DT_Q8 (1–5) | P4: Downtime GAP score (calc) | Q4: DEP_Q9 (0/1/2) | R4: DEP_Q10 (0/1/2) | S4: DEP_Q11 (0/1/2) | T4: Dependency points (calc) | U4: IT dependency level (calc) | V4: Notes | W4: Customer model (B2B/B2C) | X4: Revenue concentration (Low/Med/High) | Y4: Entity Type (Important/Essential)
A5: 1 | B5: SaaS (high IT, strong resilience) | C5: 75000000 | D5: J – IT/Telecom | H5: 3 | I5: 3 | J5: 1 | K5: 1 | L5: 1 | M5: 1 | N5: 1 | O5: 1 | P5: =IF(COUNT(H5:O5)=0,"",((AVERAGE(H5:O5)-1)/4)*100) -> 12.5 | Q5: 2 | R5: 1 | S5: 1 | T5: =IF(COUNTA(Q5:S5)=0,"",SUM(Q5:S5)) -> 4 | U5: =IF(T5="","",IF(T5<=1,"Low",IF(T5<=3,"Medium","High"))) -> High | V5: Customer-facing; good backup/IR | W5: B2B | X5: Medium | Y5: Important
A6: 2 | B6: Manufacturing (high IT, medium resilience) | C6: 75000000 | D6: C – Manufacturing | E6: High | F6: 50 | H6: 3 | I6: 1 | J6: 1 | K6: 1 | L6: 1 | M6: 1 | N6: 1 | O6: 1 | P6: =IF(COUNT(H6:O6)=0,"",((AVERAGE(H6:O6)-1)/4)*100) -> 6.25 | Q6: 1 | R6: 1 | S6: 1 | T6: =IF(COUNTA(Q6:S6)=0,"",SUM(Q6:S6)) -> 3 | U6: =IF(T6="","",IF(T6<=1,"Low",IF(T6<=3,"Medium","High"))) -> Medium | V6: ERP/production; moderate controls | W6: B2C | X6: Low | Y6: Important
A7: 3 | B7: Pro services (medium IT, medium resilience) | C7: 35000000 | D7: M – Professional Services | E7: Medium | F7: 60 | H7: 1 | I7: 2 | J7: 3 | K7: 1 | L7: 2 | M7: 3 | N7: 1 | O7: 2 | P7: =IF(COUNT(H7:O7)=0,"",((AVERAGE(H7:O7)-1)/4)*100) -> 21.875 | Q7: 2 | R7: 2 | S7: 1 | T7: =IF(COUNTA(Q7:S7)=0,"",SUM(Q7:S7)) -> 5 | U7: =IF(T7="","",IF(T7<=1,"Low",IF(T7<=3,"Medium","High"))) -> High | V7: Work can partially shift | W7: B2B | X7: Medium | Y7: Not sure
A8: 4 | B8: Logistics (high IT, low resilience) | C8: 60000000 | D8: H – Transportation | E8: High | F8: 40 | P8: =IF(COUNT(H8:O8)=0,"",((AVERAGE(H8:O8)-1)/4)*100) | T8: =IF(COUNTA(Q8:S8)=0,"",SUM(Q8:S8)) | U8: =IF(T8="","",IF(T8<=1,"Low",IF(T8<=3,"Medium","High"))) | V8: Dispatch and tracking depend on IT | W8: B2C | X8: Medium | Y8: Important
A9: 5 | B9: Retail (medium IT, strong resilience) | C9: 50000000 | D9: G – Wholesale/Retail | E9: Medium | F9: 80 | P9: =IF(COUNT(H9:O9)=0,"",((AVERAGE(H9:O9)-1)/4)*100) | T9: =IF(COUNTA(Q9:S9)=0,"",SUM(Q9:S9)) | U9: =IF(T9="","",IF(T9<=1,"Low",IF(T9<=3,"Medium","High"))) | V9: POS/ecom; tested restores | W9: B2B | X9: Medium | Y9: Important
A10: 6 | B10: Healthcare (high IT, low resilience) | C10: 90000000 | D10: Q – Healthcare | E10: High | F10: 35 | P10: =IF(COUNT(H10:O10)=0,"",((AVERAGE(H10:O10)-1)/4)*100) | T10: =IF(COUNTA(Q10:S10)=0,"",SUM(Q10:S10)) | U10: =IF(T10="","",IF(T10<=1,"Low",IF(T10<=3,"Medium","High"))) | V10: High criticality; weak processes | W10: B2B | X10: Medium | Y10: Important
A11: 7 | B11: Finance (high IT, strong resilience) | C11: 120000000 | D11: K – Financial Services | E11: High | F11: 78 | P11: =IF(COUNT(H11:O11)=0,"",((AVERAGE(H11:O11)-1)/4)*100) | T11: =IF(COUNTA(Q11:S11)=0,"",SUM(Q11:S11)) | U11: =IF(T11="","",IF(T11<=1,"Low",IF(T11<=3,"Medium","High"))) | V11: Tight ops; strong monitoring | W11: B2B | X11: Medium | Y11: Important
A12: 8 | B12: Public (medium IT, medium resilience) | C12: 40000000 | D12: O – Public Administration | E12: Medium | F12: 65 | P12: =IF(COUNT(H12:O12)=0,"",((AVERAGE(H12:O12)-1)/4)*100) | T12: =IF(COUNTA(Q12:S12)=0,"",SUM(Q12:S12)) | U12: =IF(T12="","",IF(T12<=1,"Low",IF(T12<=3,"Medium","High"))) | V12: Mixed IT reliance | W12: B2B | X12: Medium | Y12: Important
A13: 9 | B13: Energy (high IT, medium resilience) | C13: 110000000 | D13: D – Energy/Utilities | E13: High | F13: 62 | P13: =IF(COUNT(H13:O13)=0,"",((AVERAGE(H13:O13)-1)/4)*100) | T13: =IF(COUNTA(Q13:S13)=0,"",SUM(Q13:S13)) | U13: =IF(T13="","",IF(T13<=1,"Low",IF(T13<=3,"Medium","High"))) | V13: Operational tech dependencies | W13: B2B | X13: Medium | Y13: Important
A14: 10 | B14: Manufacturing 24/7 override example | C14: 80000000 | D14: C – Manufacturing | E14: High | F14: 55 | G14: 365 | P14: =IF(COUNT(H14:O14)=0,"",((AVERAGE(H14:O14)-1)/4)*100) | T14: =IF(COUNTA(Q14:S14)=0,"",SUM(Q14:S14)) | U14: =IF(T14="","",IF(T14<=1,"Low",IF(T14<=3,"Medium","High"))) | V14: Override business days to 365 to test sensitivity | W14: B2B | X14: Medium | Y14: Important
P15: =IF(COUNT(H15:O15)=0,"",((AVERAGE(H15:O15)-1)/4)*100) | Y15: Important
P16: =IF(COUNT(H16:O16)=0,"",((AVERAGE(H16:O16)-1)/4)*100) | Y16: Important
P17: =IF(COUNT(H17:O17)=0,"",((AVERAGE(H17:O17)-1)/4)*100) | Y17: Important
P18: =IF(COUNT(H18:O18)=0,"",((AVERAGE(H18:O18)-1)/4)*100) | Y18: Important
P19: =IF(COUNT(H19:O19)=0,"",((AVERAGE(H19:O19)-1)/4)*100) | Y19: Important
P20: =IF(COUNT(H20:O20)=0,"",((AVERAGE(H20:O20)-1)/4)*100) | Y20: Important
P21: =IF(COUNT(H21:O21)=0,"",((AVERAGE(H21:O21)-1)/4)*100) | Y21: Important
P22: =IF(COUNT(H22:O22)=0,"",((AVERAGE(H22:O22)-1)/4)*100) | Y22: Important
P23: =IF(COUNT(H23:O23)=0,"",((AVERAGE(H23:O23)-1)/4)*100) | Y23: Important
P24: =IF(COUNT(H24:O24)=0,"",((AVERAGE(H24:O24)-1)/4)*100) | Y24: Important
P25: =IF(COUNT(H25:O25)=0,"",((AVERAGE(H25:O25)-1)/4)*100) | Y25: Important
P26: =IF(COUNT(H26:O26)=0,"",((AVERAGE(H26:O26)-1)/4)*100) | Y26: Important
... P200: =IF(COUNT(H200:O200)=0,"",((AVERAGE(H200:O200)-1)/4)*100) | Y200: Important

Sheet IBM_Calibration
A1: IBM Industry | B1: IBM Cost (USD m) | C1: Min Cost | D1: Max Cost | E1: Range | F1: Cost - Min | G1: Sector Factor (0.90–1.10)
A2: Healthcare | B2: 7.42 | C2: =MIN($B$2:$B$18) -> 2.86 | D2: =MAX($B$2:$B$18) -> 7.42 | E2: =D2-C2 -> 4.56 | F2: =B2-$C$2 -> 4.56 | G2: =0.9 + (F2/$E$2)*0.2 -> 1.1
A3: Financial | B3: 5.56 | C3: =$C$2 -> 2.86 | D3: =$D$2 -> 7.42 | E3: =$E$2 -> 4.56 | F3: =B3-$C$2 -> 2.7 | G3: =0.9 + (F3/$E$2)*0.2 -> 1.0184211
A4: Industrial | B4: 5 | C4: =$C$2 -> 2.86 | D4: =$D$2 -> 7.42 | E4: =$E$2 -> 4.56 | F4: =B4-$C$2 -> 2.14 | G4: =0.9 + (F4/$E$2)*0.2 -> 0.99385965
A5: Energy | B5: 4.83 | C5: =$C$2 -> 2.86 | D5: =$D$2 -> 7.42 | E5: =$E$2 -> 4.56 | F5: =B5-$C$2 -> 1.97 | G5: =0.9 + (F5/$E$2)*0.2 -> 0.98640351
A6: Technology | B6: 4.79 | C6: =$C$2 -> 2.86 | D6: =$D$2 -> 7.42 | E6: =$E$2 -> 4.56 | F6: =B6-$C$2 -> 1.93 | G6: =0.9 + (F6/$E$2)*0.2 -> 0.98464912
A7: Pharmaceuticals | B7: 4.61 | C7: =$C$2 -> 2.86 | D7: =$D$2 -> 7.42 | E7: =$E$2 -> 4.56 | F7: =B7-$C$2 -> 1.75 | G7: =0.9 + (F7/$E$2)*0.2 -> 0.97675439
A8: Services | B8: 4.56 | C8: =$C$2 -> 2.86 | D8: =$D$2 -> 7.42 | E8: =$E$2 -> 4.56 | F8: =B8-$C$2 -> 1.7 | G8: =0.9 + (F8/$E$2)*0.2 -> 0.9745614
A9: Entertainment | B9: 4.43 | C9: =$C$2 -> 2.86 | D9: =$D$2 -> 7.42 | E9: =$E$2 -> 4.56 | F9: =B9-$C$2 -> 1.57 | G9: =0.9 + (F9/$E$2)*0.2 -> 0.96885965
A10: Media | B10: 4.22 | C10: =$C$2 -> 2.86 | D10: =$D$2 -> 7.42 | E10: =$E$2 -> 4.56 | F10: =B10-$C$2 -> 1.36 | G10: =0.9 + (F10/$E$2)*0.2 -> 0.95964912
A11: Hospitality | B11: 4.03 | C11: =$C$2 -> 2.86 | D11: =$D$2 -> 7.42 | E11: =$E$2 -> 4.56 | F11: =B11-$C$2 -> 1.17 | G11: =0.9 + (F11/$E$2)*0.2 -> 0.95131579
A12: Transportation | B12: 3.98 | C12: =$C$2 -> 2.86 | D12: =$D$2 -> 7.42 | E12: =$E$2 -> 4.56 | F12: =B12-$C$2 -> 1.12 | G12: =0.9 + (F12/$E$2)*0.2 -> 0.94912281
A13: Education | B13: 3.8 | C13: =$C$2 -> 2.86 | D13: =$D$2 -> 7.42 | E13: =$E$2 -> 4.56 | F13: =B13-$C$2 -> 0.94 | G13: =0.9 + (F13/$E$2)*0.2 -> 0.94122807
A14: Research | B14: 3.79 | C14: =$C$2 -> 2.86 | D14: =$D$2 -> 7.42 | E14: =$E$2 -> 4.56 | F14: =B14-$C$2 -> 0.93 | G14: =0.9 + (F14/$E$2)*0.2 -> 0.94078947
... A18: Public | B18: 2.86 | C18: =$C$2 -> 2.86 | D18: =$D$2 -> 7.42 | E18: =$E$2 -> 4.56 | F18: =B18-$C$2 -> 0 | G18: =0.9 + (F18/$E$2)*0.2 -> 0.9

Sheet EU_Sector_Map
A1: EU Sector | B1: Mapped IBM Industry
A2: A – Agriculture | B2: Industrial
A3: B – Mining | B3: Industrial
A4: C – Manufacturing | B4: Industrial
A5: D – Energy/Utilities | B5: Energy
A6: E – Water/Waste | B6: Energy
A7: F – Construction | B7: Industrial
A8: G – Wholesale/Retail | B8: Retail
A9: H – Transportation | B9: Transportation
A10: I – Hospitality | B10: Hospitality
A11: J – IT/Telecom | B11: Technology
A12: K – Financial Services | B12: Financial
... A20: S – Other Services | B20: Services

Sheet QC_Checks
A1: CoNC Quality Control Checks | D1: Named-range robustness: key outputs are defined as workbook names (e.g., Downtime_Days, IR_Cost_Mid, Restore_Cost_Mid, EBI_Cost_Mid).
A3: IR multiplier within bounds (0.80–1.30) | B3: =IF(AND(DT_Calc!B37>=0.8,DT_Calc!B37<=1.3),"OK","ERROR") -> OK
A4: Restore multiplier within bounds (0.80–1.30) | B4: =IF(AND(DT_Calc!B47>=0.8,DT_Calc!B47<=1.3),"OK","ERROR") -> OK
A5: Downtime days within bounds (0.5–3.0) | B5: =IF(AND(DT_Calc!B16>=0.5,DT_Calc!B16<=3),"OK","ERROR") -> OK
A6: All 8 GAP questions answered | B6: =IFERROR(IF(COUNTBLANK(OFFSET(DT_Scenarios!$H$1,MATCH(DT_Calc!$B$4,DT_Scenarios!$A:$A,0)-1,0,1,8))=0,"OK","ERROR"),"ERROR") -> OK
A7: IR monotonic test (higher score lowers multiplier) | B7: =IF(DT_Calc!B37<=1.3,"OK","CHECK") -> OK
A8: Restore base lookup active (not zero) | B8: =IF(DT_Calc!B45>0,"OK","ERROR") -> OK
A10: EBI dependency multiplier within expected set (0.90/1.00/1.10) | B10: =OR(DT_Calc!B57=0.9,DT_Calc!B57=1,DT_Calc!B57=1.1) -> TRUE
A11: EBI sector adj reasonable (0.95–1.05 if sector factor 0.9–1.1) | B11: =AND(DT_Calc!B56>=0.95,DT_Calc!B56<=1.05) -> TRUE
A12: EBI cost non-negative | B12: =DT_Calc!B59>=0 -> TRUE
A14: CCL – Customer model valid (B2B/B2C) | B14: =OR(CCL_Customer_Model="B2B",CCL_Customer_Model="B2C") -> TRUE
A15: CCL – Concentration valid (Low/Medium/High) | B15: =OR(CCL_Concentration="Low",CCL_Concentration="Medium",CCL_Concentration="High") -> TRUE
A16: CCL – Base % within expected bounds (0.2%–1.2%) | B16: =AND(CCL_Base_Pct>=0.002,CCL_Base_Pct<=0.012) -> TRUE
A17: CCL – Severity adj within bounds | B17: =AND(CCL_Severity_Adj>=INDEX(tbl_CCL_Params[Value], MATCH("CCL_Severity_Min", tbl_CCL_Params[Parameter], 0)),CCL_Severity_Adj<=INDEX(tbl_CCL_Params[Value], MATCH("CCL_Severity_Max", tbl_CCL_Params[Parameter], 0))) -> TRUE
A18: CCL – IR adj within bounds (based on compression)
A20: REG – Severity adj within bounds (1.00–1.50) | B20: =IF(AND(Reg_Severity_Adj>=1,Reg_Severity_Adj<=1.5),"OK","ERROR") -> OK
A21: REG – IR adj within bounds (0.90–1.15) | B21: =IF(AND(Reg_IR_Adj>=0.9,Reg_IR_Adj<=1.15),"OK","ERROR") -> OK
A22: REG – Cost non-negative | B22: =IF(Reg_Cost_Mid>=0,"OK","ERROR") -> OK
A24: Reputation – Checks
A25: Reputation non-negative | B25: =IF(Reputation_Cost_Mid>=0,"OK","ERROR") -> OK
A26: Reputation <= CCL (sanity) | B26: =IF(Reputation_Cost_Mid<=CCL_Cost_Mid,"OK","CHECK") -> OK
A28: Governance <= IR (sanity) | B28: =IF(Governance_Cost_Mid<=IR_Cost_Mid,"OK","CHECK") -> OK
A30: Fine excluded from CoNC total | B30: Ensure Administrative_Fine_Ceiling not included in total sum
